<mujoco model="bdx-r">
  <compiler angle="radian" meshdir="meshes" autolimits="true" balanceinertia="true" />
  <default>
    <default class="bdx-r">
      <site group="5" rgba="1 0 0 1" size="0.01" />
      <default class="visual">
        <geom type="mesh" contype="0" conaffinity="0" group="2" density="0" />
      </default>
      <default class="collision">
        <geom type="capsule" group="3" material="bright_orange" contype="1" conaffinity="1" />
      </default>
    </default>
  </default>
  <asset>
    <texture type="skybox" builtin="gradient" rgb1="0.3 0.5 0.7" rgb2="0 0 0" width="512" height="512" />
    <texture name="texplane" type="2d" builtin="checker" rgb1=".2 .3 .4" rgb2=".1 0.15 0.2" width="512" height="512" mark="cross" markrgb=".8 .8 .8" />
    <material name="azure" rgba="0.00784313725490196 0.8 0.996078431372549 1" />
    <material name="white" rgba="1.0 1.0 1.0 1.0" />
    <material name="black" rgba="0.0 0.0 0.0 1.0" />
    <material name="MatPlane" reflectance="0.5" texture="texplane" texrepeat="1 1" texuniform="true" />
    <material name="silver" rgba="0.75 0.75 0.75 1.0" />
    <material name="red" rgba="1 0 0 1" />
    <material name="bright_orange" rgba="1 0.65 0 0.2" />
    <mesh name="base_link" file="base_link.stl" scale="0.001 0.001 0.001" />
    <mesh name="Left_Hip_Yaw_Motor" file="Left_Hip_Yaw_Motor.stl" scale="0.001 0.001 0.001" />
    <mesh name="Right_Hip_Yaw_Motor" file="Right_Hip_Yaw_Motor.stl" scale="0.001 0.001 0.001" />
    <mesh name="Neck_Motor" file="Neck_Motor.stl" scale="0.001 0.001 0.001" />
    <mesh name="Neck" file="Neck.stl" scale="0.001 0.001 0.001" />
    <mesh name="Bottom_Cover" file="Bottom_Cover.stl" scale="0.001 0.001 0.001" />
    <mesh name="Right_Hip_Yaw_Support" file="Right_Hip_Yaw_Support.stl" scale="0.001 0.001 0.001" />
    <mesh name="Left_Hip_Yaw_Support" file="Left_Hip_Yaw_Support.stl" scale="0.001 0.001 0.001" />
    <mesh name="Base_Top_Clamp" file="Base_Top_Clamp.stl" scale="0.001 0.001 0.001" />
    <mesh name="Head_Pitch_Motor" file="Head_Pitch_Motor.stl" scale="0.001 0.001 0.001" />
    <mesh name="Left_Holder" file="Left_Holder.stl" scale="0.001 0.001 0.001" />
    <mesh name="Top_Base_Frame" file="Top_Base_Frame.stl" scale="0.001 0.001 0.001" />
    <mesh name="Head_Pitch_Motor_Support" file="Head_Pitch_Motor_Support.stl" scale="0.001 0.001 0.001" />
    <mesh name="Head_Yaw_Motor" file="Head_Yaw_Motor.stl" scale="0.001 0.001 0.001" />
    <mesh name="Head_Roll_Connector" file="Head_Roll_Connector.stl" scale="0.001 0.001 0.001" />
    <mesh name="Head_Roll_Motor" file="Head_Roll_Motor.stl" scale="0.001 0.001 0.001" />
    <mesh name="Head_Roll_Motor_Mount" file="Head_Roll_Motor_Mount.stl" scale="0.001 0.001 0.001" />
    <mesh name="Front_Support" file="Front_Support.stl" scale="0.001 0.001 0.001" />
    <mesh name="Right_Cable_Support" file="Right_Cable_Support.stl" scale="0.001 0.001 0.001" />
    <mesh name="Head_Base_Plate" file="Head_Base_Plate.stl" scale="0.001 0.001 0.001" />
    <mesh name="Right_Eye" file="Right_Eye.stl" scale="0.001 0.001 0.001" />
    <mesh name="Front_Cover" file="Front_Cover.stl" scale="0.001 0.001 0.001" />
    <mesh name="Right_Head_Support" file="Right_Head_Support.stl" scale="0.001 0.001 0.001" />
    <mesh name="Right_Front_Cover" file="Right_Front_Cover.stl" scale="0.001 0.001 0.001" />
    <mesh name="Left_Eye" file="Left_Eye.stl" scale="0.001 0.001 0.001" />
    <mesh name="Right_Holder" file="Right_Holder.stl" scale="0.001 0.001 0.001" />
    <mesh name="Left_Head_Support" file="Left_Head_Support.stl" scale="0.001 0.001 0.001" />
    <mesh name="Left_Front_Cover" file="Left_Front_Cover.stl" scale="0.001 0.001 0.001" />
    <mesh name="Battery_Holder" file="Battery_Holder.stl" scale="0.001 0.001 0.001" />
    <mesh name="Left_Cable_Support" file="Left_Cable_Support.stl" scale="0.001 0.001 0.001" />
    <mesh name="Battery" file="Battery.stl" scale="0.001 0.001 0.001" />
    <mesh name="Back_Support" file="Back_Support.stl" scale="0.001 0.001 0.001" />
    <mesh name="Rear_Cover" file="Rear_Cover.stl" scale="0.001 0.001 0.001" />
    <mesh name="Face" file="Face.stl" scale="0.001 0.001 0.001" />
    <mesh name="Left_Hip_Top_Holder" file="Left_Hip_Top_Holder.stl" scale="0.001 0.001 0.001" />
    <mesh name="Left_Hip_Roll_Motor" file="Left_Hip_Roll_Motor.stl" scale="0.001 0.001 0.001" />
    <mesh name="Left_Hip_Roll_Connector" file="Left_Hip_Roll_Connector.stl" scale="0.001 0.001 0.001" />
    <mesh name="Left_Hip_Pitch_Motor" file="Left_Hip_Pitch_Motor.stl" scale="0.001 0.001 0.001" />
    <mesh name="Left_Upper_Leg" file="Left_Upper_Leg.stl" scale="0.001 0.001 0.001" />
    <mesh name="Left_Hip_Bottom_Holder" file="Left_Hip_Bottom_Holder.stl" scale="0.001 0.001 0.001" />
    <mesh name="Left_Knee_Motor" file="Left_Knee_Motor.stl" scale="0.001 0.001 0.001" />
    <mesh name="Left_Lower_Leg" file="Left_Lower_Leg.stl" scale="0.001 0.001 0.001" />
    <mesh name="Left_Ankle_Cover" file="Left_Ankle_Cover.stl" scale="0.001 0.001 0.001" />
    <mesh name="Left_Ankle_Motor" file="Left_Ankle_Motor.stl" scale="0.001 0.001 0.001" />
    <mesh name="Left_Foot" file="Left_Foot.stl" scale="0.001 0.001 0.001" />
    <mesh name="Left_Foot_Pad" file="Left_Foot_Pad.stl" scale="0.001 0.001 0.001" />
    <mesh name="Left_Foot_Cover" file="Left_Foot_Cover.stl" scale="0.001 0.001 0.001" />
    <mesh name="Left_Upper_Leg_Cover" file="Left_Upper_Leg_Cover.stl" scale="0.001 0.001 0.001" />
    <mesh name="Left_Lower_Leg_Cover" file="Left_Lower_Leg_Cover.stl" scale="0.001 0.001 0.001" />
    <mesh name="Left_Upper_Leg_Detail" file="Left_Upper_Leg_Detail.stl" scale="0.001 0.001 0.001" />
    <mesh name="Camera_Mount" file="Camera_Mount.stl" scale="0.001 0.001 0.001" />
    <mesh name="Rear_Antenna_Box" file="Rear_Antenna_Box.stl" scale="0.001 0.001 0.001" />
    <mesh name="Right_Hip_Top_Holder" file="Right_Hip_Top_Holder.stl" scale="0.001 0.001 0.001" />
    <mesh name="Right_Hip_Roll_Motor" file="Right_Hip_Roll_Motor.stl" scale="0.001 0.001 0.001" />
    <mesh name="Right_Hip_Roll_Connector" file="Right_Hip_Roll_Connector.stl" scale="0.001 0.001 0.001" />
    <mesh name="Right_Hip_Bottom_Holder" file="Right_Hip_Bottom_Holder.stl" scale="0.001 0.001 0.001" />
    <mesh name="Right_Hip_Pitch_Motor" file="Right_Hip_Pitch_Motor.stl" scale="0.001 0.001 0.001" />
    <mesh name="Right_Upper_Leg" file="Right_Upper_Leg.stl" scale="0.001 0.001 0.001" />
    <mesh name="Right_Knee_Motor" file="Right_Knee_Motor.stl" scale="0.001 0.001 0.001" />
    <mesh name="Right_Lower_Leg" file="Right_Lower_Leg.stl" scale="0.001 0.001 0.001" />
    <mesh name="Right_Ankle_Motor" file="Right_Ankle_Motor.stl" scale="0.001 0.001 0.001" />
    <mesh name="Right_Foot" file="Right_Foot.stl" scale="0.001 0.001 0.001" />
    <mesh name="Right_Foot_Pad" file="Right_Foot_Pad.stl" scale="0.001 0.001 0.001" />
    <mesh name="Right_Foot_Cover" file="Right_Foot_Cover.stl" scale="0.001 0.001 0.001" />
    <mesh name="Right_Upper_Leg_Cover" file="Right_Upper_Leg_Cover.stl" scale="0.001 0.001 0.001" />
    <mesh name="Right_Lower_Leg_Cover" file="Right_Lower_Leg_Cover.stl" scale="0.001 0.001 0.001" />
    <mesh name="Right_Upper_Leg_Detail" file="Right_Upper_Leg_Detail.stl" scale="0.001 0.001 0.001" />
    <mesh name="Right_Ankle_Cover" file="Right_Ankle_Cover.stl" scale="0.001 0.001 0.001" />
    <mesh name="Left_Top_Cover" file="Left_Top_Cover.stl" scale="0.001 0.001 0.001" />
    <mesh name="Right_Top_Cover" file="Right_Top_Cover.stl" scale="0.001 0.001 0.001" />
    <mesh name="imu_mount" file="imu_mount.stl" scale="0.001 0.001 0.001" />
    <mesh name="imu" file="imu.stl" scale="0.001 0.001 0.001" />
    <mesh name="Orin_Nano_Case" file="Orin_Nano_Case.stl" scale="0.001 0.001 0.001" />
    <mesh name="Right_Ear_Holder" file="Right_Ear_Holder.stl" scale="0.001 0.001 0.001" />
    <mesh name="Right_Ear_Motor" file="Right_Ear_Motor.stl" scale="0.001 0.001 0.001" />
    <mesh name="Right_Ear" file="Right_Ear.stl" scale="0.001 0.001 0.001" />
    <mesh name="Left_Ear_Holder" file="Left_Ear_Holder.stl" scale="0.001 0.001 0.001" />
    <mesh name="Left_Ear_Motor" file="Left_Ear_Motor.stl" scale="0.001 0.001 0.001" />
    <mesh name="Left_Ear" file="Left_Ear.stl" scale="0.001 0.001 0.001" />
    <mesh name="Rear_Head_Cover" file="Rear_Head_Cover.stl" scale="0.001 0.001 0.001" />
    <mesh name="Rear_Head_Plate" file="Rear_Head_Plate.stl" scale="0.001 0.001 0.001" />
  </asset>
  <worldbody>
    <body name="base_link" pos="0 0 0.25" childclass="bdx-r">
      <inertial pos="0.0285257 8.41039e-06 0.0509918" mass="1.15887" fullinertia="0.005714 0.007914 0.004476 1e-05 0.000772 5e-06" />
      <geom class="visual" mesh="base_link" material="black" />
      <body name="Left_Hip_Yaw_Motor" pos="-0.032622 0.068801 0.109598">
        <inertial pos="0.0452137 -0.0187317 0.0212523" mass="0.910444" fullinertia="0.000918 0.00088 0.001215 -1e-06 1e-06 6e-06" />
        <geom class="visual" mesh="Left_Hip_Yaw_Motor" material="black" pos="0.032622 -0.068801 -0.109598" />
        <body name="Left_Hip_Top_Holder" pos="0.04527 -0.018751 -0.0025">
          <joint name="Left_Hip_Yaw" axis="0.0 0.0 1.0" range="-0.2617993877991494 0.2617993877991494"/>
          <inertial pos="0.00162017 0.00319912 -0.0113672" mass="0.0821127" fullinertia="3.3e-05 3.5e-05 5.6e-05 -1e-06 3e-06 1e-06" />
          <geom class="visual" mesh="Left_Hip_Top_Holder" material="black" pos="-0.012648 -0.05005 -0.107098" />
          <body name="Left_Hip_Roll_Motor" pos="0.0155 0.031251 -0.017274">
            <inertial pos="-0.02116 -0.0187285 -0.0452265" mass="0.906987" fullinertia="0.001212 0.000876 0.000914 -6e-06 1e-06 1e-06" />
            <geom class="visual" mesh="Left_Hip_Roll_Motor" material="black" pos="-0.028148 -0.081301 -0.089824" />
            <body name="Left_Hip_Roll_Connector" pos="0.0025 -0.018751 -0.04527">
              <joint name="Left_Hip_Roll" axis="-1.0 0.0 0.0" range="-0.2617993877991494 0.3490658503988659"/>
              <inertial pos="0.0023355 0.0293204 9.42159e-05" mass="0.0981459" fullinertia="0.000108 2.4e-05 0.0001 1.2e-05 0 -0" />
              <geom class="visual" mesh="Left_Hip_Roll_Connector" material="black" pos="-0.030648 -0.06255 -0.044554" />
              <body name="Left_Hip_Pitch_Motor" pos="-0.008646 0.07125 0.001341">
                <joint name="Left_Hip_Pitch" axis="0.0 -1.0 0.0" range="-1.0471975511965976 0.6981317007977318"/>
                <inertial pos="5.59296e-05 0.0237521 -1.95587e-05" mass="0.910452" fullinertia="0.000918 0.001215 0.00088 -1e-06 -1e-06 -6e-06" />
                <geom class="visual" mesh="Left_Hip_Pitch_Motor" material="black" pos="-0.022002 -0.1338 -0.045895" />
                <body name="Left_Upper_Leg" pos="-0.018752 0.0025 0.04527">
                  <inertial pos="-0.0242746 0.0172653 -0.0787967" mass="0.565554" fullinertia="0.001455 0.00232 0.001546 -3.2e-05 -0.00053 -9e-06" />
                  <geom class="visual" mesh="Left_Upper_Leg" material="black" pos="-0.00325 -0.1363 -0.091165" />
                  <body name="Left_Knee_Motor" pos="-0.106013 0 -0.141269">
                    <inertial pos="0.045479 0.0212521 0.0183467" mass="0.910452" fullinertia="0.00088 0.001215 0.000918 6e-06 1e-06 -1e-06" />
                    <geom class="visual" mesh="Left_Knee_Motor" material="black" pos="0.102763 -0.1363 0.050104" />
                    <body name="Left_Lower_Leg" pos="0.045459 -0.0025 0.018291">
                      <joint name="Left_Knee" axis="0.0 1.0 0.0" range="-0.9599310885968813 1.3089969389957472"/>
                      <inertial pos="0.0122832 -0.0211551 -0.0653918" mass="0.386853" fullinertia="0.00123 0.001535 0.000412 2e-05 0.000321 -6.6e-05" />
                      <geom class="visual" mesh="Left_Lower_Leg" material="black" pos="0.057304 -0.1338 0.031813" />
                      <body name="Left_Ankle_Cover" pos="0.072419 -0.045377 -0.097579">
                        <inertial pos="-0.0272704 -0.00635427 -0.0324997" mass="0.0142021" fullinertia="7e-06 1.5e-05 7e-06 -0 -0 -0" />
                        <geom class="visual" mesh="Left_Ankle_Cover" material="azure" pos="-0.015115 -0.088423 0.129392" />
                      </body>
                      <body name="Left_Ankle_Motor" pos="0.009131 -0.00934 -0.124166">
                        <inertial pos="0.0365342 -0.0168978 -0.00724371" mass="0.43363" fullinertia="0.000297 0.000423 0.000296 -1e-06 6e-06 -2e-06" />
                        <geom class="visual" mesh="Left_Ankle_Motor" material="black" pos="0.048173 -0.12446 0.155979" />
                        <body name="Left_Foot" pos="0.036018 0.004 -0.005913">
                          <joint name="Left_Ankle" axis="-0.0 -1.0 -0.0" range="-0.785 1.2217304763960306"/>
                          <inertial pos="0.02614 -0.00466554 -0.039192" mass="0.253739" fullinertia="0.000195 0.000667 0.0006 1.9e-05 2.5e-05 -4.5e-05" />
                          <geom class="visual" mesh="Left_Foot" material="black" pos="0.012155 -0.12846 0.161892" />
                          <body name="Left_Foot_Pad" pos="0.222432 -0.025632 0.027724">
                            <inertial pos="-0.195252 0.00765129 -0.0993291" mass="0.111203" fullinertia="1.6e-05 0.000254 0.000264 0 0 -0" />
                            <geom class="visual" mesh="Left_Foot_Pad" material="black" pos="-0.210277 -0.102828 0.134168" />
                            <geom class="collision" name="left_foot_collision1" size="0.005" fromto="-0.2678 -0.0065 -0.1087  -0.1228 -0.0065 -0.1087" />
                            <geom class="collision" name="left_foot_collision2" size="0.005" fromto="-0.2628 -0.0025 -0.1087  -0.1278 -0.0025 -0.1087" />
                            <geom class="collision" name="left_foot_collision3" size="0.005" fromto="-0.2578  0.0015 -0.1087  -0.1328  0.0015 -0.1087" />
                            <geom class="collision" name="left_foot_collision4" size="0.005" fromto="-0.2578  0.0055 -0.1087  -0.1328  0.0055 -0.1087" />
                            <geom class="collision" name="left_foot_collision5" size="0.005" fromto="-0.2578  0.0095 -0.1087  -0.1328  0.0095 -0.1087" />
                            <geom class="collision" name="left_foot_collision6" size="0.005" fromto="-0.2628  0.0135 -0.1087  -0.1278  0.0135 -0.1087" />
                            <geom class="collision" name="left_foot_collision7" size="0.005" fromto="-0.2678  0.0175 -0.1087  -0.1228  0.0175 -0.1087" />
                          </body>
                          <body name="Left_Foot_Cover" pos="0.102636 0.0135 -0.048903">
                            <inertial pos="-0.053452 -0.0143058 0.0213113" mass="0.0375237" fullinertia="6.4e-05 0.000132 0.000116 2.4e-05 8e-06 5e-06" />
                            <geom class="visual" mesh="Left_Foot_Cover" material="azure" pos="-0.090481 -0.14196 0.210795" />
                          </body>
                          <site name="left_foot" pos="0.035 -0.025682 -0.071" size="0.01" rgba="1 0 0 1" />
                        </body>
                      </body>
                    </body>
                  </body>
                  <body name="Left_Upper_Leg_Cover" pos="0.058901 0.0465 -0.075069">
                    <inertial pos="-0.0409403 0.000936835 0.0389855" mass="0.0636117" fullinertia="9e-05 0.000296 0.000237 9e-06 -8e-06 5e-06" />
                    <geom class="visual" mesh="Left_Upper_Leg_Cover" material="white" pos="-0.062151 -0.1828 -0.016096" />
                    <body name="Left_Upper_Leg_Detail" pos="0.022141 0.011874 0.129718">
                      <inertial pos="-0.140135 -0.00116722 -0.114257" mass="0.0049676" fullinertia="1e-06 2e-06 1e-06 0 0 0" />
                      <geom class="visual" mesh="Left_Upper_Leg_Detail" pos="-0.084292 -0.194674 -0.145814" />
                    </body>
                  </body>
                  <body name="Left_Lower_Leg_Cover" pos="-0.10624 0.0465 -0.11194">
                    <inertial pos="0.0656069 -0.000288225 -0.0209171" mass="0.0918022" fullinertia="0.0001 0.000359 0.00029 9e-06 -5.3e-05 -3e-06" />
                    <geom class="visual" mesh="Left_Lower_Leg_Cover" material="azure" pos="0.10299 -0.1828 0.020775" />
                  </body>
                </body>
              </body>
            </body>
            <body name="Left_Hip_Bottom_Holder" pos="0 0 -0.09054">
              <inertial pos="-0.0132831 -0.0263267 -0.00296785" mass="0.060065" fullinertia="2.2e-05 2.5e-05 3.8e-05 -0 -3e-06 -0" />
              <geom class="visual" mesh="Left_Hip_Bottom_Holder" material="black" pos="-0.028148 -0.081301 0.000716" />
            </body>
          </body>
        </body>
      </body>
      <body name="Right_Hip_Yaw_Motor" pos="-0.032622 -0.068701 0.109598">
        <inertial pos="0.0453267 0.0187317 0.0212523" mass="0.910444" fullinertia="0.000918 0.00088 0.001215 -1e-06 -1e-06 -6e-06" />
        <geom class="visual" mesh="Right_Hip_Yaw_Motor" material="black" pos="0.032622 0.068701 -0.109598" />
        <body name="Right_Hip_Top_Holder" pos="0.04527 0.018751 -0.0025">
          <joint name="Right_Hip_Yaw" axis="0.0 0.0 1.0" range="-0.2617993877991494 0.2617993877991494"/>
          <inertial pos="0.00162017 -0.00319911 -0.0131072" mass="0.0821127" fullinertia="3.3e-05 3.5e-05 5.6e-05 1e-06 3e-06 -1e-06" />
          <geom class="visual" mesh="Right_Hip_Top_Holder" material="black" pos="-0.012648 0.04995 -0.107098" />
          <body name="Right_Hip_Roll_Motor" pos="0.0155 0.006251 -0.019014">
            <inertial pos="-0.02116 -0.0187735 -0.0452265" mass="0.906987" fullinertia="0.001212 0.000876 0.000914 6e-06 1e-06 -1e-06" />
            <geom class="visual" mesh="Right_Hip_Roll_Motor" material="black" pos="-0.028148 0.043699 -0.088084" />
            <body name="Right_Hip_Roll_Connector" pos="0.0025 -0.018751 -0.04527">
              <joint name="Right_Hip_Roll" axis="-1.0 0.0 0.0" range="-0.3490658503988659 0.2617993877991494"/>
              <inertial pos="0.0023355 -0.0293203 9.42157e-05" mass="0.0981459" fullinertia="0.000108 2.4e-05 0.0001 -1.2e-05 0 0" />
              <geom class="visual" mesh="Right_Hip_Roll_Connector" material="black" pos="-0.030648 0.06245 -0.042814" />
              <body name="Right_Hip_Pitch_Motor" pos="-0.008646 -0.07125 0.001341">
                <joint name="Right_Hip_Pitch" axis="0.0 1.0 0.0" range="-0.6981317007977318 1.0471975511965976"/>
                <inertial pos="5.59947e-05 -0.0237519 -1.92588e-05" mass="0.910444" fullinertia="0.000918 0.001215 0.00088 1e-06 -1e-06 6e-06" />
                <geom class="visual" mesh="Right_Hip_Pitch_Motor" material="black" pos="-0.022002 0.1337 -0.044155" />
                <body name="Right_Upper_Leg" pos="-0.018752 -0.0025 0.04527">
                  <inertial pos="-0.024281 -0.0172422 -0.0787691" mass="0.565588" fullinertia="0.001453 0.00232 0.001545 3.1e-05 -0.00053 9e-06" />
                  <geom class="visual" mesh="Right_Upper_Leg" material="black" pos="-0.00325 0.1362 -0.089425" />
                  <body name="Right_Knee_Motor" pos="-0.078844 0 -0.07752">
                    <inertial pos="0.0183097 -0.0212519 -0.0454022" mass="0.910444" fullinertia="0.00088 0.001215 0.000918 -6e-06 1e-06 1e-06" />
                    <geom class="visual" mesh="Right_Knee_Motor" material="black" pos="0.075594 0.1362 -0.011905" />
                    <body name="Right_Lower_Leg" pos="0.01829 0.0025 -0.045458">
                      <joint name="Right_Knee" axis="-0.0 -1.0 -0.0" range="-1.3089969389957472 0.9599310885968813"/>
                      <inertial pos="0.0122832 0.0211551 -0.0653918" mass="0.386853" fullinertia="0.00123 0.001535 0.000412 -2e-05 0.000321 6.6e-05" />
                      <geom class="visual" mesh="Right_Lower_Leg" material="black" pos="0.057304 0.1337 0.033553" />
                      <body name="Right_Ankle_Motor" pos="0.044717 0.00934 -0.093581">
                        <inertial pos="0.000948222 0.0168978 -0.0378287" mass="0.43363" fullinertia="0.000297 0.000423 0.000296 1e-06 6e-06 2e-06" />
                        <geom class="visual" mesh="Right_Ankle_Motor" material="black" pos="0.012587 0.12436 0.127134" />
                        <body name="Right_Foot" pos="0.000432 -0.004 -0.036498">
                          <joint name="Right_Ankle" axis="0.0 1.0 0.0" range="-1.2217304763960306 0.785"/>
                          <inertial pos="0.02614 0.00466555 -0.039192" mass="0.253739" fullinertia="0.000195 0.000667 0.0006 -1.9e-05 2.5e-05 4.5e-05" />
                          <geom class="visual" mesh="Right_Foot" material="black" pos="0.012155 0.12836 0.163632" />
                          <body name="Right_Foot_Pad" pos="0.10668 0.018025 -0.059278">
                            <inertial pos="-0.0794999 4.53063e-07 -0.0123271" mass="0.111203" fullinertia="1.6e-05 0.000254 0.000264 -0 0 0" />
                            <geom class="visual" mesh="Right_Foot_Pad" material="black" pos="-0.094525 0.110335 0.22291" />
                            <geom class="collision" name="right_foot_collision1" size="0.005" fromto="-0.152  0.014 -0.02  -0.007  0.014 -0.02" />
                            <geom class="collision" name="right_foot_collision2" size="0.005" fromto="-0.147  0.01  -0.02  -0.012  0.01  -0.02" />
                            <geom class="collision" name="right_foot_collision3" size="0.005" fromto="-0.142  0.006 -0.02  -0.017  0.006 -0.02" />
                            <geom class="collision" name="right_foot_collision4" size="0.005" fromto="-0.142  0.002 -0.02  -0.017  0.002 -0.02" />
                            <geom class="collision" name="right_foot_collision5" size="0.005" fromto="-0.142 -0.002 -0.02  -0.017 -0.002 -0.02" />
                            <geom class="collision" name="right_foot_collision6" size="0.005" fromto="-0.147 -0.006 -0.02  -0.012 -0.006 -0.02" />
                            <geom class="collision" name="right_foot_collision7" size="0.005" fromto="-0.152 -0.01  -0.02  -0.007 -0.01  -0.02" />
                          </body>
                          <body name="Right_Foot_Cover" pos="-0.041752 -0.0135 -0.042544">
                            <inertial pos="0.09107 0.0144107 0.015231" mass="0.0375241" fullinertia="6.9e-05 0.000136 0.000117 -2.5e-05 7e-06 -7e-06" />
                            <geom class="visual" mesh="Right_Foot_Cover" material="azure" pos="0.053907 0.14186 0.206176" />
                          </body>
                          <site name="right_foot" pos="0.035 0.018025 -0.071" size="0.01" rgba="1 0 0 1" />
                        </body>
                      </body>
                      <body name="Right_Ankle_Cover" pos="0.017878 0.045377 -0.162578">
                        <inertial pos="0.0272706 0.00635428 0.0324993" mass="0.0142021" fullinertia="7e-06 1.5e-05 7e-06 0 -0 0" />
                        <geom class="visual" mesh="Right_Ankle_Cover" material="azure" pos="0.039426 0.088323 0.196131" />
                      </body>
                    </body>
                  </body>
                  <body name="Right_Upper_Leg_Cover" pos="0.058901 -0.0465 -0.075069">
                    <inertial pos="-0.0409403 -0.00093683 0.0389855" mass="0.0636117" fullinertia="9e-05 0.000296 0.000237 -9e-06 -8e-06 -5e-06" />
                    <geom class="visual" mesh="Right_Upper_Leg_Cover" material="white" pos="-0.062151 0.1827 -0.014356" />
                    <body name="Right_Upper_Leg_Detail" pos="0.022141 -0.011774 0.127978">
                      <inertial pos="-0.137951 0.000535076 -0.11224" mass="0.0049676" fullinertia="1e-06 2e-06 1e-06 0 0 0" />
                      <geom class="visual" mesh="Right_Upper_Leg_Detail" material="azure" pos="-0.084292 0.194474 -0.142334" />
                    </body>
                  </body>
                  <body name="Right_Lower_Leg_Cover" pos="-0.10624 -0.0465 -0.11194">
                    <inertial pos="0.0636909 -0.00605024 -0.0174859" mass="0.0493738" fullinertia="5.4e-05 0.000184 0.000145 -2e-06 -2.8e-05 4e-06" />
                    <geom class="visual" mesh="Right_Lower_Leg_Cover" material="azure" pos="0.10299 0.1827 0.022515" />
                  </body>
                </body>
              </body>
            </body>
            <body name="Right_Hip_Bottom_Holder" pos="0 0 -0.09054">
              <inertial pos="-0.0132831 -0.0111753 -0.00296785" mass="0.060065" fullinertia="2.2e-05 2.5e-05 3.8e-05 0 -3e-06 0" />
              <geom class="visual" mesh="Right_Hip_Bottom_Holder" material="black" pos="-0.028148 0.043699 0.002456" />
            </body>
          </body>
        </body>
      </body>
      <body name="Neck_Motor" pos="0.132886 -0.0164 0.129795">
        <inertial pos="-0.0308996 0.0168978 0.0207154" mass="0.429402" fullinertia="0.000296 0.000419 0.00029 -2e-06 3e-06 -1e-06" />
        <geom class="visual" mesh="Neck_Motor" material="black" pos="-0.132886 0.0164 -0.129795" />
        <body name="Neck" pos="-0.030954 -0.004 0.019342">
          <!-- <joint name="Neck_Pitch" axis="0.0 1.0 -0.0" range="-0.3490658503988659 0.8726646259971648" /> -->
          <inertial pos="-0.0234567 0.00438569 0.0565731" mass="0.2" fullinertia="0.00022 0.00028 0.000123 1.3e-05 9.1e-05 -3.4e-05" />
          <geom class="visual" mesh="Neck" material="black" pos="-0.101932 0.0204 -0.149137" />
          <body name="Head_Pitch_Motor" pos="-0.047284 -0.00566 0.100231">
            <inertial pos="-0.017591 0.0172458 0.0112969" mass="0.214076" fullinertia="8.9e-05 7.9e-05 8.9e-05 0 -0 -1e-06" />
            <geom class="visual" mesh="Head_Pitch_Motor" material="black" pos="-0.054648 0.02606 -0.249368" />
            <body name="Head_Pitch_Motor_Support" pos="-0.017501 0 0.011149">
              <!-- <joint name="Head_Pitch" axis="0.0 1.0 0.0" range="-1.0471975511965976 0.5235987755982988" /> -->
              <inertial pos="-0.00964845 0.013235 0.0430231" mass="0.044643" fullinertia="5e-05 4.2e-05 1.9e-05 2e-06 8e-06 -8e-06" />
              <geom class="visual" mesh="Head_Pitch_Motor_Support" material="black" pos="-0.037147 0.02606 -0.260517" />
              <body name="Head_Yaw_Motor" pos="-0.017969 0.027051 0.074557">
                <inertial pos="0.0191595 -0.00811371 -0.0172459" mass="0.214075" fullinertia="8.9e-05 9e-05 7.9e-05 -0 -0 -1e-06" />
                <geom class="visual" mesh="Head_Yaw_Motor" material="black" pos="-0.019178 -0.000991 -0.335074" />
                <body name="Head_Roll_Connector" pos="0.01917 -0.007941 0">
                  <!-- <joint name="Head_Yaw" axis="0.0 0.0 -1.0" range="-0.8726646259971648 0.8726646259971648" /> -->
                  <inertial pos="0.0211308 -4.18231e-08 0.00296739" mass="0.026235" fullinertia="4e-06 1e-05 1e-05 -0 2e-06 0" />
                  <geom class="visual" mesh="Head_Roll_Connector" material="black" pos="-0.038348 0.00695 -0.335074" />
                  <body name="Head_Roll_Motor" pos="0.043997 0 -0.009">
                    <!-- <joint name="Head_Roll" axis="-1.0 0.0 0.0" range="-0.5235987755982988 0.5235987755982988" /> -->
                    <inertial pos="0.0172461 -0.000172653 -1.03471e-05" mass="0.214075" fullinertia="7.9e-05 9e-05 8.9e-05 1e-06 0 -0" />
                    <geom class="visual" mesh="Head_Roll_Motor" material="black" pos="-0.082345 0.00695 -0.326074" />
                    <body name="Head_Roll_Motor_Mount" pos="0 0.01917 -0.00794">
                      <inertial pos="0.014234 -0.0200143 -0.0108146" mass="0.0606934" fullinertia="3.3e-05 2e-05 4.5e-05 0 2e-06 1e-06" />
                      <geom class="visual" mesh="Head_Roll_Motor_Mount" material="black" pos="-0.082345 -0.01222 -0.318134" />
                      <body name="Head_Base_Plate" pos="0.0021 -0.046722 -0.021495">
                        <inertial pos="-0.0314072 0.0267588 -0.000999742" mass="0.241677" fullinertia="0.001541 0.000994 0.002535 0 -0 0" />
                        <geom class="visual" mesh="Head_Base_Plate" material="black" pos="-0.084445 0.034502 -0.296639" />
                        <body name="Right_Eye" pos="0.058598 -0.056479 0">
                          <inertial pos="0.00526735 0.0221071 0.0207912" mass="0.0111037" fullinertia="5e-06 3e-06 3e-06 -0 -0 -0" />
                          <geom class="visual" mesh="Right_Eye" material="black" pos="-0.143043 0.090981 -0.296639" />
                        </body>
                        <body name="Right_Head_Support" pos="-0.123278 -0.074652 0">
                          <inertial pos="0.0116378 -0.00188178 0.00732325" mass="0.0204368" fullinertia="7e-06 6.7e-05 7.3e-05 2.1e-05 1e-06 -1e-06" />
                          <geom class="visual" mesh="Right_Head_Support" material="black" pos="0.038833 0.109154 -0.296639" />
                          <body name="Right_Front_Cover" pos="0.202885 -0.027984 0.096418">
                            <inertial pos="-0.0520371 0.0380541 -0.0481267" mass="0.0536057" fullinertia="0.000146 0.000117 0.000202 -2.8e-05 -2.9e-05 -4e-05" />
                            <geom class="visual" mesh="Right_Front_Cover" material="azure" pos="-0.164052 0.137138 -0.393057" />
                          </body>
                        </body>
                        <body name="Left_Eye" pos="0.058598 0.109997 0">
                          <inertial pos="0.0043063 -0.0227003 0.021499" mass="0.0107599" fullinertia="4e-06 3e-06 2e-06 0 -0 0" />
                          <geom class="visual" mesh="Left_Eye" material="black" pos="-0.143043 -0.075495 -0.296639" />
                        </body>
                        <body name="Left_Head_Support" pos="-0.027747 0.157732 0">
                          <inertial pos="-0.0838932 -0.0276796 0.00732325" mass="0.0204368" fullinertia="7e-06 6.7e-05 7.3e-05 -2.1e-05 1e-06 1e-06" />
                          <geom class="visual" mesh="Left_Head_Support" material="black" pos="-0.056698 -0.12323 -0.296639" />
                          <body name="Left_Front_Cover" pos="-0.008598 -0.001727 0.010956">
                            <inertial pos="0.0640461 -0.0398635 0.0363281" mass="0.0524757" fullinertia="0.000137 0.000114 0.000191 2.5e-05 -2.8e-05 3.8e-05" />
                            <geom class="visual" mesh="Left_Front_Cover" material="azure" pos="-0.0481 -0.121503 -0.307595" />
                          </body>
                          <body name="Rear_Head_Cover" pos="-0.008598 -0.001727 0.010956">
                            <inertial pos="-0.0645317 -0.129428 0.0380851" mass="0.3" fullinertia="0.001672 0.001234 0.002699 0 -0.000203 -0" />
                            <geom class="visual" mesh="Rear_Head_Cover" material="white" pos="-0.0481 -0.121503 -0.307595" />
                            <body name="Rear_Head_Plate" pos="-0.174901 -0.091107 -0.001821">
                              <inertial pos="0.0298153 -0.0383279 -0.00723612" mass="0.0147876" fullinertia="4.2e-05 6e-06 4.8e-05 -0 1e-06 -0" />
                              <geom class="visual" mesh="Rear_Head_Plate" material="black" pos="0.126801 -0.030396 -0.305774" />
                            </body>
                          </body>
                        </body>
                        <body name="Face" pos="0.052961 -0.098148 0">
                          <inertial pos="0.0119447 0.124995 0.0280089" mass="0.0365477" fullinertia="0.000279 1.7e-05 0.000264 -0 -1e-06 -0" />
                          <geom class="visual" mesh="Face" material="white" pos="-0.137406 0.13265 -0.296639" />
                        </body>
                        <body name="Right_Ear_Holder" pos="-0.142593 -0.04359 0">
                          <inertial pos="-0.00508347 0.0135661 0.0226018" mass="0.0390892" fullinertia="1.3e-05 9e-06 8e-06 -1e-06 -0 0" />
                          <geom class="visual" mesh="Right_Ear_Holder" material="black" pos="0.058148 0.078092 -0.296639" />
                          <body name="Right_Ear_Motor" pos="-0.021543 0.004139 0.045321">
                            <inertial pos="-0.0113168 0.0172458 -0.0174602" mass="0.214076" fullinertia="9e-05 7.9e-05 8.9e-05 1e-06 -0 -0" />
                            <geom class="visual" mesh="Right_Ear_Motor" material="black" pos="0.079691 0.073953 -0.34196" />
                            <body name="Right_Ear" pos="0.000669 0 -0.019584">
                              <inertial pos="-0.0132452 -0.0234204 0.00594937" mass="0.0173303" fullinertia="1e-05 8e-06 5e-06 -0 2e-06 1e-06" />
                              <geom class="visual" mesh="Right_Ear" material="black" pos="0.079022 0.073953 -0.322376" />
                            </body>
                          </body>
                        </body>
                        <body name="Left_Ear_Holder" pos="-0.142593 0.067109 0">
                          <inertial pos="-0.00510016 0.0148343 0.0226018" mass="0.0390892" fullinertia="1.3e-05 9e-06 8e-06 1e-06 -0 -0" />
                          <geom class="visual" mesh="Left_Ear_Holder" material="black" pos="0.058148 -0.032607 -0.296639" />
                          <body name="Left_Ear_Motor" pos="-0.01245 0.024261 0.032311">
                            <inertial pos="-0.0204265 -0.0172454 -0.00445018" mass="0.214076" fullinertia="9e-05 7.9e-05 8.9e-05 -1e-06 -0 0" />
                            <geom class="visual" mesh="Left_Ear_Motor" material="black" pos="0.070598 -0.056868 -0.32895" />
                            <body name="Left_Ear" pos="-0.012545 0 0.004702">
                              <inertial pos="-0.0091544 0.0233816 -0.00532896" mass="0.0173058" fullinertia="1e-05 8e-06 5e-06 0 2e-06 -1e-06" />
                              <geom class="visual" mesh="Left_Ear" material="black" pos="0.083143 -0.056868 -0.333652" />
                            </body>
                          </body>
                        </body>
                      </body>
                    </body>
                  </body>
                </body>
              </body>
            </body>
          </body>
        </body>
      </body>
      <body name="Bottom_Cover" pos="0.040668 0.06305 -0.038646">
        <inertial pos="-0.00215712 -0.063 0.000913719" mass="0.1" fullinertia="8.3e-05 9e-06 9.1e-05 -0 -0 -0" />
        <geom class="visual" mesh="Bottom_Cover" material="white" pos="-0.040668 -0.06305 0.038646" />
      </body>
      <body name="Right_Hip_Yaw_Support" pos="0.070648 -0.0177 0.088154">
        <inertial pos="-0.00233655 -0.0297011 -0.00579523" mass="0.110967" fullinertia="6.5e-05 4.4e-05 4.5e-05 -1e-06 5e-06 1e-06" />
        <geom class="visual" mesh="Right_Hip_Yaw_Support" material="black" pos="-0.070648 0.0177 -0.088154" />
      </body>
      <body name="Left_Hip_Yaw_Support" pos="0.070648 0.0178 0.088154">
        <inertial pos="-0.00240657 0.0297873 -0.00598472" mass="0.107881" fullinertia="6.3e-05 4.2e-05 4.4e-05 1e-06 5e-06 -2e-06" />
        <geom class="visual" mesh="Left_Hip_Yaw_Support" material="black" pos="-0.070648 -0.0178 -0.088154" />
      </body>
      <body name="Base_Top_Clamp" pos="-0.041248 -0.05995 0.148898">
        <inertial pos="0.0115715 0.06 0.00483101" mass="0.0462886" fullinertia="6.4e-05 1.2e-05 7.5e-05 0 -0 -0" />
        <geom class="visual" mesh="Base_Top_Clamp" material="black" pos="0.041248 0.05995 -0.148898" />
        <body name="imu_mount" pos="0.008626 0.091249 0.01">
          <inertial pos="0.0455002 -0.031249 0.00964534" mass="0.05" fullinertia="1.5e-05 2.1e-05 3.4e-05 0 2e-06 0" />
          <geom class="visual" mesh="imu_mount" material="black" pos="0.032622 -0.031299 -0.158898" />
          <body name="imu" pos="0.00865 -0.010349 0.015">
            <inertial pos="0.00758057 -0.0209 0.0136918" mass="0.1" fullinertia="3e-06 2e-06 3e-06 0 -0 -0" />
            <geom class="visual" mesh="imu" material="black" pos="0.023972 -0.02095 -0.173898" />
          </body>
          <site name="imu" size="0.01" pos="0.05 -0.03 0.02" />
        </body>
      </body>
      <body name="Left_Holder" pos="-0.042349 0.091047 0.150304">
        <inertial pos="0.0654654 0.0202797 9.29671e-05" mass="0.0360922" fullinertia="3.2e-05 0.000147 0.000124 -1.7e-05 2.9e-05 1e-06" />
        <geom class="visual" mesh="Left_Holder" material="black" pos="0.042349 -0.091047 -0.150304" />
      </body>
      <body name="Top_Base_Frame" pos="-0.032533 0.084396 0.175919">
        <inertial pos="0.0876581 -0.084346 0.00853271" mass="0.119509" fullinertia="0.00068 0.000477 0.001154 0 -5e-06 0" />
        <geom class="visual" mesh="Top_Base_Frame" material="black" pos="0.032533 -0.084396 -0.175919" />
        <body name="Left_Top_Cover" pos="0.100005 0.014043 -0.004554">
          <inertial pos="-0.044107 -0.0100958 0.000433821" mass="0.0292609" fullinertia="1.9e-05 4.6e-05 4.1e-05 0 1e-06 6e-06" />
          <geom class="visual" mesh="Left_Top_Cover" material="white" pos="-0.067472 -0.098439 -0.171365" />
        </body>
        <body name="Right_Top_Cover" pos="0.100005 -0.182735 -0.004554">
          <inertial pos="-0.044107 0.0100958 0.000433821" mass="0.0292609" fullinertia="1.9e-05 4.6e-05 4.1e-05 -0 1e-06 -6e-06" />
          <geom class="visual" mesh="Right_Top_Cover" material="white" pos="-0.067472 0.098339 -0.171365" />
        </body>
      </body>
      <body name="Front_Support" pos="0.104552 0.01005 0.079856">
        <inertial pos="0.00267539 -0.01 -0.0165269" mass="0.184244" fullinertia="0.001929 0.000901 0.001041 0 1.1e-05 0" />
        <geom class="visual" mesh="Front_Support" material="black" pos="-0.104552 -0.01005 -0.079856" />
        <body name="Right_Cable_Support" pos="0 -0.102343 0.035039">
          <inertial pos="-0.00464424 0.0120877 -0.00294295" mass="0.0552747" fullinertia="1.5e-05 1.6e-05 1.7e-05 -2e-06 1e-06 0" />
          <geom class="visual" mesh="Right_Cable_Support" material="black" pos="-0.104552 0.092293 -0.114895" />
        </body>
        <body name="Front_Cover" pos="0.004894 -0.112243 -0.028496">
          <inertial pos="0.0350759 0.102434 0.0289549" mass="0.31919" fullinertia="0.004028 0.002471 0.002125 0 -8e-05 -0" />
          <geom class="visual" mesh="Front_Cover" material="white" pos="-0.109446 0.102193 -0.05136" />
          <body name="Camera_Mount" pos="0.177343 0.156643 0.186285">
            <inertial pos="-0.121925 -0.0515759 -0.114601" mass="0.032111" fullinertia="5.1e-05 1.6e-05 4.1e-05 -0 -1e-06 -0" />
            <geom class="visual" mesh="Camera_Mount" material="black" pos="-0.286789 -0.05445 -0.237645" />
          </body>
        </body>
        <body name="Left_Cable_Support" pos="0 0.082343 0.035039">
          <inertial pos="-0.00464424 -0.0120877 -0.00294295" mass="0.0552747" fullinertia="1.5e-05 1.6e-05 1.7e-05 2e-06 1e-06 -0" />
          <geom class="visual" mesh="Left_Cable_Support" material="black" pos="-0.104552 -0.092393 -0.114895" />
        </body>
        <body name="Orin_Nano_Case" pos="0.01 -0.02 0">
          <inertial pos="0.029169 -0.00680733 -0.0560365" mass="0.5" fullinertia="0.000811 0.000527 0.000367 -1.4e-05 2e-06 1.6e-05" />
          <geom class="visual" mesh="Orin_Nano_Case" material="black" pos="-0.114552 0.00995 -0.079856" />
        </body>
      </body>
      <body name="Right_Holder" pos="-0.042349 -0.090947 0.150304">
        <inertial pos="0.0661003 -0.0203252 -0.000478187" mass="0.0361128" fullinertia="3.2e-05 0.000147 0.000124 1.7e-05 2.9e-05 -1e-06" />
        <geom class="visual" mesh="Right_Holder" material="black" pos="0.042349 0.090947 -0.150304" />
      </body>
      <body name="Battery_Holder" pos="-0.042025 5e-05 0.002134">
        <inertial pos="-0.0112596 -1.37984e-08 0.0742143" mass="0.162092" fullinertia="0.000431 0.000313 0.000128 -0 1e-05 -0" />
        <geom class="visual" mesh="Battery_Holder" material="black" pos="0.042025 -5e-05 -0.002134" />
        <body name="Battery" pos="0.091613 -0.02775 0.230592">
          <inertial pos="-0.147625 0.02745 -0.131786" mass="1.07309" fullinertia="0.002821 0.002743 0.001123 -0 -3.4e-05 0" />
          <geom class="visual" mesh="Battery" material="black" pos="-0.049588 0.0277 -0.232726" />
        </body>
        <body name="Back_Support" pos="-0.018024 0 0">
          <inertial pos="-0.0161042 0.00083864 0.0763859" mass="0.198185" fullinertia="0.000997 0.00052 0.000641 1e-06 5.1e-05 -4e-06" />
          <geom class="visual" mesh="Back_Support" material="black" pos="0.060049 -5e-05 -0.002134" />
          <body name="Rear_Cover" pos="0.005701 -0.014557 -0.031856">
            <inertial pos="-0.0379426 0.0154429 0.0814396" mass="0.318197" fullinertia="0.00246 0.001841 0.001533 0 0.000357 -0" />
            <geom class="visual" mesh="Rear_Cover" material="white" pos="0.054348 0.014507 0.029722" />
            <body name="Rear_Antenna_Box" pos="-0.089906 -0.033615 0.123682">
              <inertial pos="-0.0226373 0.0495508 -0.00812351" mass="0.0411709" fullinertia="9.7e-05 4.9e-05 5.6e-05 -0 1e-06 -0" />
              <geom class="visual" mesh="Rear_Antenna_Box" material="white" pos="0.144254 0.048122 -0.09396" />
            </body>
          </body>
        </body>
      </body>
      <freejoint />
      <geom class="collision" name="base_collision" size="0.12" fromto="-0.09 0 0.07 0.09 0 0.07" />
    </body>
  </worldbody>
  <actuator>
    <!-- Left leg -->
    <position name="Left_Hip_Yaw_servo"   joint="Left_Hip_Yaw"   kp="1"/>
    <position name="Left_Hip_Roll_servo"  joint="Left_Hip_Roll"  kp="1"/>
    <position name="Left_Hip_Pitch_servo" joint="Left_Hip_Pitch" kp="1"/>
    <position name="Left_Knee_servo"      joint="Left_Knee"      kp="1"/>
    <position name="Left_Ankle_servo"     joint="Left_Ankle"     kp="1"/>
    <!-- Right leg -->
    <position name="Right_Hip_Yaw_servo"   joint="Right_Hip_Yaw"   kp="1"/>
    <position name="Right_Hip_Roll_servo"  joint="Right_Hip_Roll"  kp="1"/>
    <position name="Right_Hip_Pitch_servo" joint="Right_Hip_Pitch" kp="1"/>
    <position name="Right_Knee_servo"      joint="Right_Knee"      kp="1"/>
    <position name="Right_Ankle_servo"     joint="Right_Ankle"     kp="1"/>
  </actuator>
  <sensor>
    <gyro name="imu_ang_vel" site="imu" />
    <velocimeter name="imu_lin_vel" site="imu" />
    <accelerometer name="imu_lin_acc" site="imu" />
    <subtreeangmom name="root_angmom" body="base_link" />
  </sensor>
</mujoco>
